<?xml version="1.0"?>
<robot xmlns:xacro="http://ros.org/wiki/xacro">

<xacro:property name="mmTom" value="0.001" />
<xacro:property name="mm2Tom2" value="${0.001*0.001}" />

<xacro:property name="PI" value="3.14159265359" />
<xacro:property name="PI_2" value="1.57079632679" />
<xacro:property name="SF" value="0.03937" /> <!-- Scale factor for meshes -->

<xacro:property name="cos_26" value="0.89879991307" />
<xacro:property name="sin_26" value="0.43835911792" />

<xacro:property name="toRad" value="${PI/180.0}" />

<!-- LINKS -->
<!-- This links are defined in order to be compliant with http://www.ros.org/reps/rep-0120.html#coordinate-frames
and to define the end effectors of the robot-->


<!-- The coordinate frame called torso is attached to the lowest body of the model which is a parent of l_gripper, r_gripper and gaze. -->
 <link name="torso"/>

  <link name ="DWL">
    <inertial>
      <origin xyz="-0.04610869 0.02232230 -0.02249514" rpy="0 0 0"/>
      <mass value="1.44965471"/>
      <inertia ixx="0.01096760"  ixy="0.00111556"  ixz="0.00030030" iyy="0.00409572" iyz="0.00054456" izz="0.01143795" />
    </inertial>
    <visual>
      <origin xyz="0.0 0.0 0.0" rpy="0 0 0"/>
      <geometry name="DWL_visual">
        <mesh filename="package://bigman_urdf/meshes/TorsoRoll.STL" scale="0.001 0.001 0.001" />
      </geometry>
      <material name="dark_grey"/>
    </visual>
    <collision>
      <origin xyz="0.0 0.0 0.0" rpy="0 0 0"/>
      <geometry name="DWL_collision">
        <mesh filename="package://bigman_urdf/meshes/simple/TorsoRoll.STL" scale="0.001 0.001 0.001" />
      </geometry>             
    </collision>
  </link>

  <link name ="DWS">
    <inertial>
      <origin xyz="0.00010203 0.00928164 0.08113610" rpy="0 0 0"/>
      <mass value="5.28825567"/>
      <inertia ixx="0.01628069"  ixy="-0.00000323"  ixz="0.00001424" iyy="0.01424286" iyz="0.00075458" izz="0.00994169" />
    </inertial>
    <visual>
      <origin xyz="0.0 0.0 0.0" rpy="0 0 0"/>
      <geometry name="DWS_visual">
        <mesh filename="package://bigman_urdf/meshes/TorsoYawPitch.STL" scale="0.001 0.001 0.001" />
      </geometry>
      <material name="dark_grey"/>
    </visual>
    <collision>
      <origin xyz="0.0 0.0 0.0" rpy="0 0 0"/>
      <geometry name="DWS_collision">
        <mesh filename="package://bigman_urdf/meshes/simple/TorsoYawPitch.STL" scale="0.001 0.001 0.001" />
      </geometry>             
    </collision>
  </link>

  <link name ="DWYTorso">
    <inertial>
      <origin xyz="-0.10981228 -0.00551229 -0.06272896" rpy="0 0 0"/>
      <mass value="22.38913469"/>
      <inertia ixx="0.15989993"  ixy="0.00087514"  ixz="0.01598045" iyy="0.11274359" iyz="0.00019540" izz="0.21318148" />
    </inertial>
    <visual>
      <origin xyz="0.0 0.0 0.0" rpy="0 0 0"/>
      <geometry name="DWYTorso_visual">
<xacro:if value="${BIGMAN_OLD_CHEST}">
        <mesh filename="package://bigman_urdf/meshes/Chest.STL" scale="0.001 0.001 0.001" />
</xacro:if>
<xacro:unless value="${BIGMAN_OLD_CHEST}">
        <mesh filename="package://bigman_urdf/meshes/NewChest.STL" scale="0.001 0.001 0.001" />
</xacro:unless>
      </geometry>
      <material name="blue"/>
    </visual>
    <collision>
      <origin xyz="0.0 0.0 0.0" rpy="0 0 0"/>
      <geometry name="DWYTorso_collision">
<xacro:if value="${BIGMAN_OLD_CHEST}">
        <mesh filename="package://bigman_urdf/meshes/simple/Chest.STL" scale="0.001 0.001 0.001" />
</xacro:if>
<xacro:unless value="${BIGMAN_OLD_CHEST}">
        <mesh filename="package://bigman_urdf/meshes/simple/NewChest.STL" scale="0.001 0.001 0.001" />
</xacro:unless>
      </geometry>             
    </collision>
  </link>

<!-- JOINTS -->
<joint name="torso_joint" type="fixed">
    <parent link="DWYTorso"/>
    <child link="torso"/>
    <origin xyz="0.0 0 0.0" rpy="0 0 0" /> 
</joint>

<joint name="WaistLat" type="revolute"> 
    <parent link="Waist"/>
    <child link="DWL"/>
    <origin xyz="0.0715192 0 0.195982" rpy="0 0 0" />
    <axis xyz="${cos_26} 0 ${sin_26}" />
    <limit velocity="6.283" effort="120" lower="${-35.0*toRad}" upper="${35.0*toRad}" />
    <dynamics friction="0" damping="3.0"/> 
</joint>

  <joint name="WaistSag" type="revolute"> 
    <parent link="DWL"/>
    <child link="DWS"/>
    <origin xyz="0 0 0" rpy="0 0 0" />
    <axis xyz="0 1 0" />
    <limit velocity="6.283" effort="220" lower="${-20.0*toRad}" upper="${80.0*toRad}" />
    <dynamics friction="0" damping="3.0"/>
  </joint>

  <joint name="WaistYaw" type="revolute">
    <parent link="DWS"/>
    <child link="DWYTorso"/>
    <origin xyz="0 0 0.22275" rpy="0 0 0" />
    <axis xyz="0 0 1" />
    <limit velocity="6.283" effort="120" lower="${-120.0*toRad}" upper="${120.0*toRad}" />
    <dynamics friction="0" damping="3.0"/>
  </joint>

</robot>
